<?xml version="1.0" ?>
<!-- =================================================================================== -->
<!-- |    This document was autogenerated by xacro from robot.urdf.xacro               | -->
<!-- |    EDITING THIS FILE BY HAND IS NOT RECOMMENDED                                 | -->
<!-- =================================================================================== -->
<robot name="robot">
  <material name="blue">
    <color rgba="1.0 1.0 1.0 1.0"/>
  </material>
  <material name="green">
    <color rgba="1.0 1.0 1.0 1.0"/>
  </material>
  <material name="red">
    <color rgba="1.0 1.0 1.0 1.0"/>
  </material>
  <link name="base_link"/>
  <joint name="chassis_joint" type="fixed">
    <parent link="base_link"/>
    <child link="chassis"/>
    <origin xyz="0 0 0"/>
  </joint>
  <link name="chassis">
    <inertial>
      <origin rpy="0 0 -1.5707963267948966" xyz="3.84321e-10 9.33138e-10 0.0163291"/>
      <!-- Please change mass and inertia matrix to reflect better aprox -->
      <mass value="16.479"/>
      <inertia ixx="0.174135" ixy="1.42629e-09" ixz="-7.38887e-11" iyy="0.119734" iyz="-1.54691e-10" izz="0.279608"/>
    </inertial>
    <visual>
      <origin rpy="0 -0 -1.5707963267948966" xyz="0 0 0"/>
      <geometry>
        <mesh filename="package://rivals/description/assets/part_1__6ed075fc00e4d09673dc30a20c0a2d67.stl"/>
      </geometry>
      <material name="part_1__6ed075fc00e4d09673dc30a20c0a2d67_material">
        <color rgba="0.615686 0.811765 0.929412 1"/>
      </material>
    </visual>
    <collision>
      <origin rpy="0 -0 -1.5707963267948966" xyz="0 0 0"/>
      <geometry>
        <mesh filename="package://rivals/description/assets/part_1__6ed075fc00e4d09673dc30a20c0a2d67.stl"/>
      </geometry>
    </collision>
  </link>
  <joint name="FL_wheel_joint" type="continuous">
    <origin rpy="-1.5707963267948966 0 0" xyz="0.11829359 0.11703082 0"/>
    <parent link="chassis"/>
    <child link="FL_wheel_link"/>
    <axis xyz="0 0 1"/>
  </joint>
  <link name="FL_wheel_link">
    <visual>
      <geometry>
        <cylinder length="0.03643720" radius="0.035369"/>
      </geometry>
      <material name="red"/>
    </visual>
    <collision>
      <geometry>
        <sphere radius="0.035369"/>
      </geometry>
    </collision>
    <inertial>
      <origin rpy="0 0 0" xyz="0 0 0"/>
      <mass value="1"/>
      <inertia ixx="0.0004233806689033333" ixy="0.0" ixz="0.0" iyy="0.0004233806689033333" iyz="0.0" izz="0.0006254830804999999"/>
    </inertial>
  </link>
  <joint name="BL_wheel_joint" type="continuous">
    <origin rpy="-1.5707963267948966 0 0" xyz="-0.11829359 0.11703082 0"/>
    <parent link="chassis"/>
    <child link="BL_wheel_link"/>
    <axis xyz="0 0 1"/>
  </joint>
  <link name="BL_wheel_link">
    <visual>
      <geometry>
        <cylinder length="0.03643720" radius="0.035369"/>
      </geometry>
      <material name="red"/>
    </visual>
    <collision>
      <geometry>
        <sphere radius="0.035369"/>
      </geometry>
    </collision>
    <inertial>
      <origin rpy="0 0 0" xyz="0 0 0"/>
      <mass value="1"/>
      <inertia ixx="0.0004233806689033333" ixy="0.0" ixz="0.0" iyy="0.0004233806689033333" iyz="0.0" izz="0.0006254830804999999"/>
    </inertial>
  </link>
  <joint name="FR_wheel_joint" type="continuous">
    <origin rpy="1.5707963267948966 0 0" xyz="0.11829359 -0.11703082 0"/>
    <parent link="chassis"/>
    <child link="FR_wheel_link"/>
    <axis xyz="0 0 -1"/>
  </joint>
  <link name="FR_wheel_link">
    <visual>
      <geometry>
        <cylinder length="0.03643720" radius="0.035369"/>
      </geometry>
      <material name="red"/>
    </visual>
    <collision>
      <geometry>
        <sphere radius="0.035369"/>
      </geometry>
    </collision>
    <inertial>
      <origin rpy="0 0 0" xyz="0 0 0"/>
      <mass value="1"/>
      <inertia ixx="0.0004233806689033333" ixy="0.0" ixz="0.0" iyy="0.0004233806689033333" iyz="0.0" izz="0.0006254830804999999"/>
    </inertial>
  </link>
  <joint name="BR_wheel_joint" type="continuous">
    <origin rpy="1.5707963267948966 0 0" xyz="-0.11829359 -0.11703082 0"/>
    <parent link="chassis"/>
    <child link="BR_wheel_link"/>
    <axis xyz="0 0 -1"/>
  </joint>
  <link name="BR_wheel_link">
    <visual>
      <geometry>
        <cylinder length="0.03643720" radius="0.035369"/>
      </geometry>
      <material name="red"/>
    </visual>
    <collision>
      <geometry>
        <sphere radius="0.035369"/>
      </geometry>
    </collision>
    <inertial>
      <origin rpy="0 0 0" xyz="0 0 0"/>
      <mass value="1"/>
      <inertia ixx="0.0004233806689033333" ixy="0.0" ixz="0.0" iyy="0.0004233806689033333" iyz="0.0" izz="0.0006254830804999999"/>
    </inertial>
  </link>
  <!-- <joint name="camera_joint" type="fixed"> -->
  <!--   <parent link="base_link"/> -->
  <!--   <child  link="camera_link"/> -->
  <!--   <origin xyz="0.05 -0.1 0.1" rpy="0 0 0"/> -->
  <!-- </joint> -->
  <!-- <link name="camera_link"> -->
  <!-- </link> -->
  <!---->
  <!-- <joint name="depth_camera_joint" type="fixed"> -->
  <!--   <parent link="base_link"/> -->
  <!--   <child  link="depth_camera_link"/> -->
  <!--   <origin xyz="0.05 0.1 0.1" rpy="0 0 0"/> -->
  <!-- </joint> -->
  <!-- <link name="depth_camera_link"> -->
  <!-- </link> -->
  <!-- Want Isaac to consume the joint speeds not /cmd_vel -->
  <ros2_control name="robot" type="system">
    <hardware>
      <plugin>topic_based_ros2_control/TopicBasedSystem</plugin>
      <param name="joint_commands_topic">/robot/joint_command</param>
      <param name="joint_states_topic">/robot/joint_states</param>
      <param name="sum_wrapped_joint_states">true</param>
    </hardware>
    <joint name="FL_wheel_joint">
      <command_interface name="velocity">
          </command_interface>
      <state_interface name="position"/>
      <state_interface name="velocity"/>
    </joint>
    <joint name="FR_wheel_joint">
      <command_interface name="velocity">
          </command_interface>
      <state_interface name="position"/>
      <state_interface name="velocity"/>
    </joint>
    <joint name="BL_wheel_joint">
      <command_interface name="velocity">
          </command_interface>
      <state_interface name="position"/>
      <state_interface name="velocity"/>
    </joint>
    <joint name="BR_wheel_joint">
      <command_interface name="velocity">
          </command_interface>
      <state_interface name="position"/>
      <state_interface name="velocity"/>
    </joint>
  </ros2_control>
  <!-- <xacro:include filename="camera.xacro" /> -->
  <!-- <xacro:include filename="depth_camera.xacro" /> -->
</robot>
